<?xml version="1.0"?>
<robot name="arm">
    <link name="base">
        
    </link>

    <joint name="joint_0" type="revolute">
        <parent link="base"/>
        <child link="link0"/>
        <origin xyz="0.0 0.0 0.0"/>
        <axis xyz="0.0 0.0 1"/>
        <limit lower="-1.5708" upper="1.5708" effort="1000" velocity="5"/>
    </joint>

    <link name="link0">
        
    </link>

    <joint name="joint_1" type="revolute">
        <parent link="link0"/>
        <child link="link1"/>
        <origin xyz="0.0 0.340 -0.07"/>
        <axis xyz="1 0.0 0.0"/>
        <limit lower="0" upper="1.5708" effort="1000" velocity="5"/>
    </joint>

    <link name="link1">
        
    </link>

    <joint name="jonit_fixed" type="fixed">
        <parent link="link1"/>
        <child link="link2"/>
        <origin xyz="0.0 0.0 -0.120" rpy="0.0 0.0 0.0"/>
    </joint>
    
    <link name="link2">
        
    </link>

</robot>