<?xml version="1.0"?>
<robot name="nebulizador_arm">
    <link name="base_link">
        <visual>
            <origin xyz="0 0 0" rpy="0 0 0"/>
            <geometry>
                <cylinder radius="0.016" length="0.034"/>   
            </geometry>
        </visual>
    </link>

    <link name="link1">
        <inertial>
            <mass value="0.385"/>
            <origin xyz="0 0 0" rpy="0 0 0"/>
            <inertia ixx="0.001934" ixy="-0.00004188" ixz="0.00001696" iyy="0.0004250" iyz="0.0005391" izz="0.001805"/>
        </inertial>

<!--        <collision>
            <origin xyz="" rpy=""/>
            <geometry>
                <mesh filename="package://nebulizador_arm/meshes/"/>
            </geometry>
        </collision> -->
        
        <visual>
            <origin rpy="0 0 3.1416" xyz="0 0 0"/>
            <geometry>
                <mesh filename="package://nebulizador_arm/meshes/Eslabon1.dae"/>
            </geometry>
        </visual>
    </link>

    <joint name="link1_joint" type="revolute">
        <parent link="base_link"/>
        <child link="link1"/>
        <origin xyz="0 0 0.017" rpy="0 0 0"/>
        <axis xyz="0.0 0.0 1"/>
        <limit lower="-1.5708" upper="1.5708" effort="1000" velocity="5"/>
    <!--    <dynamics damping="50" friction="1"/> -->
    </joint>

    <link name="link2">
        <inertial>
            <mass value="0.348"/>
            <origin xyz="0 0 0" rpy="0 0 0"/>
            <inertia ixx="0.0008054" ixy="0.000005522" ixz="-0.00002630" iyy="0.0008908" iyz="0.0002229" izz="0.0004215"/>
        </inertial>

<!--        <collision>
            <origin xyz="" rpy=""/>
            <geometry>
                <mesh filename="package://nebulizador_arm/meshes/"/>
            </geometry>
        </collision> -->
        
        <visual>
            <origin xyz="0 0.004 0.035" rpy="0 0 3.1416"/>
            <geometry>
                <mesh filename="package://nebulizador_arm/meshes/Eslabon2.dae"/>
            </geometry>
        </visual>        
    </link>

    <joint name="link2_joint" type="revolute">
        <parent link="link1"/>
        <child link="link2"/>
        <origin xyz="-0.00838 0.190 0.06964" rpy="0 0 0"/>
        <axis xyz="1 0 0"/>
        <limit lower="0.785398" upper="-0.785398" effort="1000" velocity="5"/>
        <!--    <dynamics damping="50" friction="1"/> -->
    </joint>

<!--    <link name="link3">
        <visual>
            <origin rpy="0 1.5708 0" xyz="0 0 0"/>
            <geometry>
                <cylinder radius="0.008" length="0.01715"/>
            </geometry>
        </visual>        
    </link>
-->
    <transmission name="tran1">
        <type>transmission_interface/SimpleTransmission</type>
        <joint name="link1_joint">
            <hardwareInterface>hardware_interface/PositionJointInterface</hardwareInterface>
        </joint>
        <actuator name="motor1">
            <hardwareInterface>hardware_interface/PositionJointInterface</hardwareInterface>
            <mechanicalReduction>1</mechanicalReduction>
        </actuator>
    </transmission>

    <transmission name="tran2">
        <type>transmission_interface/SimpleTransmission</type>
        <joint name="link2_joint">
            <hardwareInterface>hardware_interface/PositionJointInterface</hardwareInterface>
        </joint>
        <actuator name="motor2">
            <hardwareInterface>hardware_interface/PositionJointInterface</hardwareInterface>
            <mechanicalReduction>1</mechanicalReduction>
        </actuator>
    </transmission>

    <gazebo>
        <plugin name="gazebo_ros_control" filename="libgazebo_ros_control.so">
            <robotNamespace>/nebulizador_arm</robotNamespace>
        </plugin>
    </gazebo>
</robot>